[2025-07-16T20:15:39.128-0700] {processor.py:157} INFO - Started process (PID=10829) to work on /Volumes/Personal Drive/GitHub/gdpr-ccpa-risk-pipeline/dags/gdpr_ccpa_risk_pipeline.py
[2025-07-16T20:15:39.134-0700] {processor.py:829} INFO - Processing file /Volumes/Personal Drive/GitHub/gdpr-ccpa-risk-pipeline/dags/gdpr_ccpa_risk_pipeline.py for tasks to queue
[2025-07-16T20:15:39.134-0700] {logging_mixin.py:151} INFO - [2025-07-16T20:15:39.134-0700] {dagbag.py:539} INFO - Filling up the DagBag from /Volumes/Personal Drive/GitHub/gdpr-ccpa-risk-pipeline/dags/gdpr_ccpa_risk_pipeline.py
[2025-07-16T20:15:39.962-0700] {logging_mixin.py:151} INFO - [2025-07-16T20:15:39.937-0700] {dagbag.py:347} ERROR - Failed to import: /Volumes/Personal Drive/GitHub/gdpr-ccpa-risk-pipeline/dags/gdpr_ccpa_risk_pipeline.py
Traceback (most recent call last):
  File "/Volumes/Personal Drive/GitHub/gdpr-ccpa-risk-pipeline/venv/lib/python3.11/site-packages/airflow/models/dagbag.py", line 343, in parse
    loader.exec_module(new_module)
  File "<frozen importlib._bootstrap_external>", line 940, in exec_module
  File "<frozen importlib._bootstrap>", line 241, in _call_with_frames_removed
  File "/Volumes/Personal Drive/GitHub/gdpr-ccpa-risk-pipeline/dags/gdpr_ccpa_risk_pipeline.py", line 33, in <module>
    with DAG(
         ^^^^
TypeError: DAG.__init__() got an unexpected keyword argument 'load_examples'
[2025-07-16T20:15:40.013-0700] {processor.py:841} WARNING - No viable dags retrieved from /Volumes/Personal Drive/GitHub/gdpr-ccpa-risk-pipeline/dags/gdpr_ccpa_risk_pipeline.py
[2025-07-16T20:15:43.235-0700] {processor.py:179} INFO - Processing /Volumes/Personal Drive/GitHub/gdpr-ccpa-risk-pipeline/dags/gdpr_ccpa_risk_pipeline.py took 4.124 seconds
[2025-07-16T20:16:59.103-0700] {processor.py:157} INFO - Started process (PID=10871) to work on /Volumes/Personal Drive/GitHub/gdpr-ccpa-risk-pipeline/dags/gdpr_ccpa_risk_pipeline.py
[2025-07-16T20:16:59.116-0700] {processor.py:829} INFO - Processing file /Volumes/Personal Drive/GitHub/gdpr-ccpa-risk-pipeline/dags/gdpr_ccpa_risk_pipeline.py for tasks to queue
[2025-07-16T20:16:59.117-0700] {logging_mixin.py:151} INFO - [2025-07-16T20:16:59.117-0700] {dagbag.py:539} INFO - Filling up the DagBag from /Volumes/Personal Drive/GitHub/gdpr-ccpa-risk-pipeline/dags/gdpr_ccpa_risk_pipeline.py
[2025-07-16T20:17:00.654-0700] {logging_mixin.py:151} INFO - [2025-07-16T20:17:00.552-0700] {dagbag.py:347} ERROR - Failed to import: /Volumes/Personal Drive/GitHub/gdpr-ccpa-risk-pipeline/dags/gdpr_ccpa_risk_pipeline.py
Traceback (most recent call last):
  File "/Volumes/Personal Drive/GitHub/gdpr-ccpa-risk-pipeline/venv/lib/python3.11/site-packages/airflow/models/dagbag.py", line 343, in parse
    loader.exec_module(new_module)
  File "<frozen importlib._bootstrap_external>", line 940, in exec_module
  File "<frozen importlib._bootstrap>", line 241, in _call_with_frames_removed
  File "/Volumes/Personal Drive/GitHub/gdpr-ccpa-risk-pipeline/dags/gdpr_ccpa_risk_pipeline.py", line 33, in <module>
    with DAG(
         ^^^^
TypeError: DAG.__init__() got an unexpected keyword argument 'load_examples'
[2025-07-16T20:17:00.672-0700] {processor.py:841} WARNING - No viable dags retrieved from /Volumes/Personal Drive/GitHub/gdpr-ccpa-risk-pipeline/dags/gdpr_ccpa_risk_pipeline.py
[2025-07-16T20:17:04.148-0700] {processor.py:179} INFO - Processing /Volumes/Personal Drive/GitHub/gdpr-ccpa-risk-pipeline/dags/gdpr_ccpa_risk_pipeline.py took 5.043 seconds
[2025-07-16T20:18:26.824-0700] {processor.py:157} INFO - Started process (PID=10912) to work on /Volumes/Personal Drive/GitHub/gdpr-ccpa-risk-pipeline/dags/gdpr_ccpa_risk_pipeline.py
[2025-07-16T20:18:26.844-0700] {processor.py:829} INFO - Processing file /Volumes/Personal Drive/GitHub/gdpr-ccpa-risk-pipeline/dags/gdpr_ccpa_risk_pipeline.py for tasks to queue
[2025-07-16T20:18:26.845-0700] {logging_mixin.py:151} INFO - [2025-07-16T20:18:26.844-0700] {dagbag.py:539} INFO - Filling up the DagBag from /Volumes/Personal Drive/GitHub/gdpr-ccpa-risk-pipeline/dags/gdpr_ccpa_risk_pipeline.py
[2025-07-16T20:18:27.217-0700] {logging_mixin.py:151} INFO - [2025-07-16T20:18:27.191-0700] {dagbag.py:347} ERROR - Failed to import: /Volumes/Personal Drive/GitHub/gdpr-ccpa-risk-pipeline/dags/gdpr_ccpa_risk_pipeline.py
Traceback (most recent call last):
  File "/Volumes/Personal Drive/GitHub/gdpr-ccpa-risk-pipeline/venv/lib/python3.11/site-packages/airflow/models/dagbag.py", line 343, in parse
    loader.exec_module(new_module)
  File "<frozen importlib._bootstrap_external>", line 940, in exec_module
  File "<frozen importlib._bootstrap>", line 241, in _call_with_frames_removed
  File "/Volumes/Personal Drive/GitHub/gdpr-ccpa-risk-pipeline/dags/gdpr_ccpa_risk_pipeline.py", line 33, in <module>
    with DAG(
         ^^^^
TypeError: DAG.__init__() got an unexpected keyword argument 'load_examples'
[2025-07-16T20:18:27.224-0700] {processor.py:841} WARNING - No viable dags retrieved from /Volumes/Personal Drive/GitHub/gdpr-ccpa-risk-pipeline/dags/gdpr_ccpa_risk_pipeline.py
[2025-07-16T20:18:30.905-0700] {processor.py:179} INFO - Processing /Volumes/Personal Drive/GitHub/gdpr-ccpa-risk-pipeline/dags/gdpr_ccpa_risk_pipeline.py took 4.092 seconds
[2025-07-16T20:19:29.477-0700] {processor.py:157} INFO - Started process (PID=11113) to work on /Volumes/Personal Drive/GitHub/gdpr-ccpa-risk-pipeline/dags/gdpr_ccpa_risk_pipeline.py
[2025-07-16T20:19:29.515-0700] {processor.py:829} INFO - Processing file /Volumes/Personal Drive/GitHub/gdpr-ccpa-risk-pipeline/dags/gdpr_ccpa_risk_pipeline.py for tasks to queue
[2025-07-16T20:19:29.521-0700] {logging_mixin.py:151} INFO - [2025-07-16T20:19:29.517-0700] {dagbag.py:539} INFO - Filling up the DagBag from /Volumes/Personal Drive/GitHub/gdpr-ccpa-risk-pipeline/dags/gdpr_ccpa_risk_pipeline.py
[2025-07-16T20:19:30.232-0700] {logging_mixin.py:151} INFO - [2025-07-16T20:19:30.172-0700] {dagbag.py:347} ERROR - Failed to import: /Volumes/Personal Drive/GitHub/gdpr-ccpa-risk-pipeline/dags/gdpr_ccpa_risk_pipeline.py
Traceback (most recent call last):
  File "/Volumes/Personal Drive/GitHub/gdpr-ccpa-risk-pipeline/venv/lib/python3.11/site-packages/airflow/models/dagbag.py", line 343, in parse
    loader.exec_module(new_module)
  File "<frozen importlib._bootstrap_external>", line 940, in exec_module
  File "<frozen importlib._bootstrap>", line 241, in _call_with_frames_removed
  File "/Volumes/Personal Drive/GitHub/gdpr-ccpa-risk-pipeline/dags/gdpr_ccpa_risk_pipeline.py", line 33, in <module>
    with DAG(
         ^^^^
TypeError: DAG.__init__() got an unexpected keyword argument 'load_examples'
[2025-07-16T20:19:30.233-0700] {processor.py:841} WARNING - No viable dags retrieved from /Volumes/Personal Drive/GitHub/gdpr-ccpa-risk-pipeline/dags/gdpr_ccpa_risk_pipeline.py
[2025-07-16T20:19:33.846-0700] {processor.py:179} INFO - Processing /Volumes/Personal Drive/GitHub/gdpr-ccpa-risk-pipeline/dags/gdpr_ccpa_risk_pipeline.py took 4.377 seconds
[2025-07-16T20:20:26.820-0700] {processor.py:157} INFO - Started process (PID=11180) to work on /Volumes/Personal Drive/GitHub/gdpr-ccpa-risk-pipeline/dags/gdpr_ccpa_risk_pipeline.py
[2025-07-16T20:20:26.832-0700] {processor.py:829} INFO - Processing file /Volumes/Personal Drive/GitHub/gdpr-ccpa-risk-pipeline/dags/gdpr_ccpa_risk_pipeline.py for tasks to queue
[2025-07-16T20:20:26.833-0700] {logging_mixin.py:151} INFO - [2025-07-16T20:20:26.833-0700] {dagbag.py:539} INFO - Filling up the DagBag from /Volumes/Personal Drive/GitHub/gdpr-ccpa-risk-pipeline/dags/gdpr_ccpa_risk_pipeline.py
[2025-07-16T20:20:27.497-0700] {logging_mixin.py:151} INFO - [2025-07-16T20:20:27.487-0700] {dagbag.py:347} ERROR - Failed to import: /Volumes/Personal Drive/GitHub/gdpr-ccpa-risk-pipeline/dags/gdpr_ccpa_risk_pipeline.py
Traceback (most recent call last):
  File "/Volumes/Personal Drive/GitHub/gdpr-ccpa-risk-pipeline/venv/lib/python3.11/site-packages/airflow/models/dagbag.py", line 343, in parse
    loader.exec_module(new_module)
  File "<frozen importlib._bootstrap_external>", line 940, in exec_module
  File "<frozen importlib._bootstrap>", line 241, in _call_with_frames_removed
  File "/Volumes/Personal Drive/GitHub/gdpr-ccpa-risk-pipeline/dags/gdpr_ccpa_risk_pipeline.py", line 33, in <module>
    with DAG(
         ^^^^
TypeError: DAG.__init__() got an unexpected keyword argument 'load_examples'
[2025-07-16T20:20:27.512-0700] {processor.py:841} WARNING - No viable dags retrieved from /Volumes/Personal Drive/GitHub/gdpr-ccpa-risk-pipeline/dags/gdpr_ccpa_risk_pipeline.py
[2025-07-16T20:20:31.005-0700] {processor.py:179} INFO - Processing /Volumes/Personal Drive/GitHub/gdpr-ccpa-risk-pipeline/dags/gdpr_ccpa_risk_pipeline.py took 4.213 seconds
[2025-07-16T20:21:31.158-0700] {processor.py:157} INFO - Started process (PID=11220) to work on /Volumes/Personal Drive/GitHub/gdpr-ccpa-risk-pipeline/dags/gdpr_ccpa_risk_pipeline.py
[2025-07-16T20:21:31.189-0700] {processor.py:829} INFO - Processing file /Volumes/Personal Drive/GitHub/gdpr-ccpa-risk-pipeline/dags/gdpr_ccpa_risk_pipeline.py for tasks to queue
[2025-07-16T20:21:31.212-0700] {logging_mixin.py:151} INFO - [2025-07-16T20:21:31.211-0700] {dagbag.py:539} INFO - Filling up the DagBag from /Volumes/Personal Drive/GitHub/gdpr-ccpa-risk-pipeline/dags/gdpr_ccpa_risk_pipeline.py
[2025-07-16T20:21:33.240-0700] {logging_mixin.py:151} INFO - [2025-07-16T20:21:33.208-0700] {dagbag.py:347} ERROR - Failed to import: /Volumes/Personal Drive/GitHub/gdpr-ccpa-risk-pipeline/dags/gdpr_ccpa_risk_pipeline.py
Traceback (most recent call last):
  File "/Volumes/Personal Drive/GitHub/gdpr-ccpa-risk-pipeline/venv/lib/python3.11/site-packages/airflow/models/dagbag.py", line 343, in parse
    loader.exec_module(new_module)
  File "<frozen importlib._bootstrap_external>", line 940, in exec_module
  File "<frozen importlib._bootstrap>", line 241, in _call_with_frames_removed
  File "/Volumes/Personal Drive/GitHub/gdpr-ccpa-risk-pipeline/dags/gdpr_ccpa_risk_pipeline.py", line 33, in <module>
    with DAG(
         ^^^^
TypeError: DAG.__init__() got an unexpected keyword argument 'load_examples'
[2025-07-16T20:21:33.240-0700] {processor.py:841} WARNING - No viable dags retrieved from /Volumes/Personal Drive/GitHub/gdpr-ccpa-risk-pipeline/dags/gdpr_ccpa_risk_pipeline.py
[2025-07-16T20:21:39.561-0700] {processor.py:179} INFO - Processing /Volumes/Personal Drive/GitHub/gdpr-ccpa-risk-pipeline/dags/gdpr_ccpa_risk_pipeline.py took 8.421 seconds
[2025-07-16T20:22:39.445-0700] {processor.py:157} INFO - Started process (PID=11250) to work on /Volumes/Personal Drive/GitHub/gdpr-ccpa-risk-pipeline/dags/gdpr_ccpa_risk_pipeline.py
[2025-07-16T20:22:39.479-0700] {processor.py:829} INFO - Processing file /Volumes/Personal Drive/GitHub/gdpr-ccpa-risk-pipeline/dags/gdpr_ccpa_risk_pipeline.py for tasks to queue
[2025-07-16T20:22:39.479-0700] {logging_mixin.py:151} INFO - [2025-07-16T20:22:39.479-0700] {dagbag.py:539} INFO - Filling up the DagBag from /Volumes/Personal Drive/GitHub/gdpr-ccpa-risk-pipeline/dags/gdpr_ccpa_risk_pipeline.py
[2025-07-16T20:22:40.340-0700] {logging_mixin.py:151} INFO - [2025-07-16T20:22:40.320-0700] {dagbag.py:347} ERROR - Failed to import: /Volumes/Personal Drive/GitHub/gdpr-ccpa-risk-pipeline/dags/gdpr_ccpa_risk_pipeline.py
Traceback (most recent call last):
  File "/Volumes/Personal Drive/GitHub/gdpr-ccpa-risk-pipeline/venv/lib/python3.11/site-packages/airflow/models/dagbag.py", line 343, in parse
    loader.exec_module(new_module)
  File "<frozen importlib._bootstrap_external>", line 940, in exec_module
  File "<frozen importlib._bootstrap>", line 241, in _call_with_frames_removed
  File "/Volumes/Personal Drive/GitHub/gdpr-ccpa-risk-pipeline/dags/gdpr_ccpa_risk_pipeline.py", line 33, in <module>
    with DAG(
         ^^^^
TypeError: DAG.__init__() got an unexpected keyword argument 'load_examples'
[2025-07-16T20:22:40.345-0700] {processor.py:841} WARNING - No viable dags retrieved from /Volumes/Personal Drive/GitHub/gdpr-ccpa-risk-pipeline/dags/gdpr_ccpa_risk_pipeline.py
[2025-07-16T20:22:43.278-0700] {processor.py:179} INFO - Processing /Volumes/Personal Drive/GitHub/gdpr-ccpa-risk-pipeline/dags/gdpr_ccpa_risk_pipeline.py took 3.834 seconds
[2025-07-16T20:23:38.000-0700] {processor.py:157} INFO - Started process (PID=11289) to work on /Volumes/Personal Drive/GitHub/gdpr-ccpa-risk-pipeline/dags/gdpr_ccpa_risk_pipeline.py
[2025-07-16T20:23:38.023-0700] {processor.py:829} INFO - Processing file /Volumes/Personal Drive/GitHub/gdpr-ccpa-risk-pipeline/dags/gdpr_ccpa_risk_pipeline.py for tasks to queue
[2025-07-16T20:23:38.024-0700] {logging_mixin.py:151} INFO - [2025-07-16T20:23:38.023-0700] {dagbag.py:539} INFO - Filling up the DagBag from /Volumes/Personal Drive/GitHub/gdpr-ccpa-risk-pipeline/dags/gdpr_ccpa_risk_pipeline.py
[2025-07-16T20:23:39.365-0700] {logging_mixin.py:151} INFO - [2025-07-16T20:23:39.327-0700] {dagbag.py:347} ERROR - Failed to import: /Volumes/Personal Drive/GitHub/gdpr-ccpa-risk-pipeline/dags/gdpr_ccpa_risk_pipeline.py
Traceback (most recent call last):
  File "/Volumes/Personal Drive/GitHub/gdpr-ccpa-risk-pipeline/venv/lib/python3.11/site-packages/airflow/models/dagbag.py", line 343, in parse
    loader.exec_module(new_module)
  File "<frozen importlib._bootstrap_external>", line 940, in exec_module
  File "<frozen importlib._bootstrap>", line 241, in _call_with_frames_removed
  File "/Volumes/Personal Drive/GitHub/gdpr-ccpa-risk-pipeline/dags/gdpr_ccpa_risk_pipeline.py", line 33, in <module>
    with DAG(
         ^^^^
TypeError: DAG.__init__() got an unexpected keyword argument 'load_examples'
[2025-07-16T20:23:39.365-0700] {processor.py:841} WARNING - No viable dags retrieved from /Volumes/Personal Drive/GitHub/gdpr-ccpa-risk-pipeline/dags/gdpr_ccpa_risk_pipeline.py
[2025-07-16T20:23:42.206-0700] {processor.py:179} INFO - Processing /Volumes/Personal Drive/GitHub/gdpr-ccpa-risk-pipeline/dags/gdpr_ccpa_risk_pipeline.py took 4.207 seconds
[2025-07-16T20:24:40.871-0700] {processor.py:157} INFO - Started process (PID=11331) to work on /Volumes/Personal Drive/GitHub/gdpr-ccpa-risk-pipeline/dags/gdpr_ccpa_risk_pipeline.py
[2025-07-16T20:24:40.905-0700] {processor.py:829} INFO - Processing file /Volumes/Personal Drive/GitHub/gdpr-ccpa-risk-pipeline/dags/gdpr_ccpa_risk_pipeline.py for tasks to queue
[2025-07-16T20:24:40.908-0700] {logging_mixin.py:151} INFO - [2025-07-16T20:24:40.908-0700] {dagbag.py:539} INFO - Filling up the DagBag from /Volumes/Personal Drive/GitHub/gdpr-ccpa-risk-pipeline/dags/gdpr_ccpa_risk_pipeline.py
[2025-07-16T20:24:41.222-0700] {logging_mixin.py:151} INFO - [2025-07-16T20:24:41.213-0700] {dagbag.py:347} ERROR - Failed to import: /Volumes/Personal Drive/GitHub/gdpr-ccpa-risk-pipeline/dags/gdpr_ccpa_risk_pipeline.py
Traceback (most recent call last):
  File "/Volumes/Personal Drive/GitHub/gdpr-ccpa-risk-pipeline/venv/lib/python3.11/site-packages/airflow/models/dagbag.py", line 343, in parse
    loader.exec_module(new_module)
  File "<frozen importlib._bootstrap_external>", line 940, in exec_module
  File "<frozen importlib._bootstrap>", line 241, in _call_with_frames_removed
  File "/Volumes/Personal Drive/GitHub/gdpr-ccpa-risk-pipeline/dags/gdpr_ccpa_risk_pipeline.py", line 33, in <module>
    with DAG(
         ^^^^
TypeError: DAG.__init__() got an unexpected keyword argument 'load_examples'
[2025-07-16T20:24:41.224-0700] {processor.py:841} WARNING - No viable dags retrieved from /Volumes/Personal Drive/GitHub/gdpr-ccpa-risk-pipeline/dags/gdpr_ccpa_risk_pipeline.py
[2025-07-16T20:24:44.234-0700] {processor.py:179} INFO - Processing /Volumes/Personal Drive/GitHub/gdpr-ccpa-risk-pipeline/dags/gdpr_ccpa_risk_pipeline.py took 3.364 seconds
[2025-07-16T20:25:27.978-0700] {processor.py:157} INFO - Started process (PID=11365) to work on /Volumes/Personal Drive/GitHub/gdpr-ccpa-risk-pipeline/dags/gdpr_ccpa_risk_pipeline.py
[2025-07-16T20:25:27.997-0700] {processor.py:829} INFO - Processing file /Volumes/Personal Drive/GitHub/gdpr-ccpa-risk-pipeline/dags/gdpr_ccpa_risk_pipeline.py for tasks to queue
[2025-07-16T20:25:27.997-0700] {logging_mixin.py:151} INFO - [2025-07-16T20:25:27.997-0700] {dagbag.py:539} INFO - Filling up the DagBag from /Volumes/Personal Drive/GitHub/gdpr-ccpa-risk-pipeline/dags/gdpr_ccpa_risk_pipeline.py
[2025-07-16T20:25:28.141-0700] {logging_mixin.py:151} INFO - [2025-07-16T20:25:28.134-0700] {dagbag.py:347} ERROR - Failed to import: /Volumes/Personal Drive/GitHub/gdpr-ccpa-risk-pipeline/dags/gdpr_ccpa_risk_pipeline.py
Traceback (most recent call last):
  File "/Volumes/Personal Drive/GitHub/gdpr-ccpa-risk-pipeline/venv/lib/python3.11/site-packages/airflow/models/dagbag.py", line 343, in parse
    loader.exec_module(new_module)
  File "<frozen importlib._bootstrap_external>", line 940, in exec_module
  File "<frozen importlib._bootstrap>", line 241, in _call_with_frames_removed
  File "/Volumes/Personal Drive/GitHub/gdpr-ccpa-risk-pipeline/dags/gdpr_ccpa_risk_pipeline.py", line 33, in <module>
    with DAG(
         ^^^^
TypeError: DAG.__init__() got an unexpected keyword argument 'load_examples'
[2025-07-16T20:25:28.142-0700] {processor.py:841} WARNING - No viable dags retrieved from /Volumes/Personal Drive/GitHub/gdpr-ccpa-risk-pipeline/dags/gdpr_ccpa_risk_pipeline.py
[2025-07-16T20:25:28.544-0700] {processor.py:179} INFO - Processing /Volumes/Personal Drive/GitHub/gdpr-ccpa-risk-pipeline/dags/gdpr_ccpa_risk_pipeline.py took 0.566 seconds
[2025-07-16T20:26:26.312-0700] {processor.py:157} INFO - Started process (PID=11380) to work on /Volumes/Personal Drive/GitHub/gdpr-ccpa-risk-pipeline/dags/gdpr_ccpa_risk_pipeline.py
[2025-07-16T20:26:26.316-0700] {processor.py:829} INFO - Processing file /Volumes/Personal Drive/GitHub/gdpr-ccpa-risk-pipeline/dags/gdpr_ccpa_risk_pipeline.py for tasks to queue
[2025-07-16T20:26:26.327-0700] {logging_mixin.py:151} INFO - [2025-07-16T20:26:26.327-0700] {dagbag.py:539} INFO - Filling up the DagBag from /Volumes/Personal Drive/GitHub/gdpr-ccpa-risk-pipeline/dags/gdpr_ccpa_risk_pipeline.py
[2025-07-16T20:26:27.594-0700] {logging_mixin.py:151} INFO - [2025-07-16T20:26:27.593-0700] {dagbag.py:347} ERROR - Failed to import: /Volumes/Personal Drive/GitHub/gdpr-ccpa-risk-pipeline/dags/gdpr_ccpa_risk_pipeline.py
Traceback (most recent call last):
  File "/Volumes/Personal Drive/GitHub/gdpr-ccpa-risk-pipeline/venv/lib/python3.11/site-packages/airflow/models/dagbag.py", line 343, in parse
    loader.exec_module(new_module)
  File "<frozen importlib._bootstrap_external>", line 940, in exec_module
  File "<frozen importlib._bootstrap>", line 241, in _call_with_frames_removed
  File "/Volumes/Personal Drive/GitHub/gdpr-ccpa-risk-pipeline/dags/gdpr_ccpa_risk_pipeline.py", line 33, in <module>
    with DAG(
         ^^^^
TypeError: DAG.__init__() got an unexpected keyword argument 'load_examples'
[2025-07-16T20:26:27.594-0700] {processor.py:841} WARNING - No viable dags retrieved from /Volumes/Personal Drive/GitHub/gdpr-ccpa-risk-pipeline/dags/gdpr_ccpa_risk_pipeline.py
[2025-07-16T20:26:31.207-0700] {processor.py:179} INFO - Processing /Volumes/Personal Drive/GitHub/gdpr-ccpa-risk-pipeline/dags/gdpr_ccpa_risk_pipeline.py took 4.915 seconds
[2025-07-16T20:27:31.281-0700] {processor.py:157} INFO - Started process (PID=11421) to work on /Volumes/Personal Drive/GitHub/gdpr-ccpa-risk-pipeline/dags/gdpr_ccpa_risk_pipeline.py
[2025-07-16T20:27:31.307-0700] {processor.py:829} INFO - Processing file /Volumes/Personal Drive/GitHub/gdpr-ccpa-risk-pipeline/dags/gdpr_ccpa_risk_pipeline.py for tasks to queue
[2025-07-16T20:27:31.308-0700] {logging_mixin.py:151} INFO - [2025-07-16T20:27:31.308-0700] {dagbag.py:539} INFO - Filling up the DagBag from /Volumes/Personal Drive/GitHub/gdpr-ccpa-risk-pipeline/dags/gdpr_ccpa_risk_pipeline.py
[2025-07-16T20:27:31.999-0700] {logging_mixin.py:151} INFO - [2025-07-16T20:27:31.949-0700] {dagbag.py:347} ERROR - Failed to import: /Volumes/Personal Drive/GitHub/gdpr-ccpa-risk-pipeline/dags/gdpr_ccpa_risk_pipeline.py
Traceback (most recent call last):
  File "/Volumes/Personal Drive/GitHub/gdpr-ccpa-risk-pipeline/venv/lib/python3.11/site-packages/airflow/models/dagbag.py", line 343, in parse
    loader.exec_module(new_module)
  File "<frozen importlib._bootstrap_external>", line 940, in exec_module
  File "<frozen importlib._bootstrap>", line 241, in _call_with_frames_removed
  File "/Volumes/Personal Drive/GitHub/gdpr-ccpa-risk-pipeline/dags/gdpr_ccpa_risk_pipeline.py", line 33, in <module>
    with DAG(
         ^^^^
TypeError: DAG.__init__() got an unexpected keyword argument 'load_examples'
[2025-07-16T20:27:32.009-0700] {processor.py:841} WARNING - No viable dags retrieved from /Volumes/Personal Drive/GitHub/gdpr-ccpa-risk-pipeline/dags/gdpr_ccpa_risk_pipeline.py
[2025-07-16T20:27:36.183-0700] {processor.py:179} INFO - Processing /Volumes/Personal Drive/GitHub/gdpr-ccpa-risk-pipeline/dags/gdpr_ccpa_risk_pipeline.py took 4.941 seconds
[2025-07-16T20:28:47.017-0700] {processor.py:157} INFO - Started process (PID=11461) to work on /Volumes/Personal Drive/GitHub/gdpr-ccpa-risk-pipeline/dags/gdpr_ccpa_risk_pipeline.py
[2025-07-16T20:28:47.081-0700] {processor.py:829} INFO - Processing file /Volumes/Personal Drive/GitHub/gdpr-ccpa-risk-pipeline/dags/gdpr_ccpa_risk_pipeline.py for tasks to queue
[2025-07-16T20:28:47.111-0700] {logging_mixin.py:151} INFO - [2025-07-16T20:28:47.096-0700] {dagbag.py:539} INFO - Filling up the DagBag from /Volumes/Personal Drive/GitHub/gdpr-ccpa-risk-pipeline/dags/gdpr_ccpa_risk_pipeline.py
[2025-07-16T20:28:49.383-0700] {logging_mixin.py:151} INFO - [2025-07-16T20:28:49.271-0700] {dagbag.py:347} ERROR - Failed to import: /Volumes/Personal Drive/GitHub/gdpr-ccpa-risk-pipeline/dags/gdpr_ccpa_risk_pipeline.py
Traceback (most recent call last):
  File "/Volumes/Personal Drive/GitHub/gdpr-ccpa-risk-pipeline/venv/lib/python3.11/site-packages/airflow/models/dagbag.py", line 343, in parse
    loader.exec_module(new_module)
  File "<frozen importlib._bootstrap_external>", line 940, in exec_module
  File "<frozen importlib._bootstrap>", line 241, in _call_with_frames_removed
  File "/Volumes/Personal Drive/GitHub/gdpr-ccpa-risk-pipeline/dags/gdpr_ccpa_risk_pipeline.py", line 21, in <module>
    from scripts.fetch_policy_data      import fetch_policy_data
ModuleNotFoundError: No module named 'scripts'
[2025-07-16T20:28:49.383-0700] {processor.py:841} WARNING - No viable dags retrieved from /Volumes/Personal Drive/GitHub/gdpr-ccpa-risk-pipeline/dags/gdpr_ccpa_risk_pipeline.py
[2025-07-16T20:49:56.681-0700] {processor.py:157} INFO - Started process (PID=12106) to work on /Volumes/Personal Drive/GitHub/gdpr-ccpa-risk-pipeline/dags/gdpr_ccpa_risk_pipeline.py
[2025-07-16T20:49:56.713-0700] {processor.py:829} INFO - Processing file /Volumes/Personal Drive/GitHub/gdpr-ccpa-risk-pipeline/dags/gdpr_ccpa_risk_pipeline.py for tasks to queue
[2025-07-16T20:49:56.713-0700] {logging_mixin.py:151} INFO - [2025-07-16T20:49:56.713-0700] {dagbag.py:539} INFO - Filling up the DagBag from /Volumes/Personal Drive/GitHub/gdpr-ccpa-risk-pipeline/dags/gdpr_ccpa_risk_pipeline.py
[2025-07-16T20:49:57.709-0700] {logging_mixin.py:151} INFO - [2025-07-16T20:49:57.627-0700] {dagbag.py:347} ERROR - Failed to import: /Volumes/Personal Drive/GitHub/gdpr-ccpa-risk-pipeline/dags/gdpr_ccpa_risk_pipeline.py
Traceback (most recent call last):
  File "/Volumes/Personal Drive/GitHub/gdpr-ccpa-risk-pipeline/venv/lib/python3.11/site-packages/airflow/models/dagbag.py", line 343, in parse
    loader.exec_module(new_module)
  File "<frozen importlib._bootstrap_external>", line 940, in exec_module
  File "<frozen importlib._bootstrap>", line 241, in _call_with_frames_removed
  File "/Volumes/Personal Drive/GitHub/gdpr-ccpa-risk-pipeline/dags/gdpr_ccpa_risk_pipeline.py", line 21, in <module>
    from scripts.fetch_policy_data      import fetch_policy_data
ModuleNotFoundError: No module named 'scripts'
[2025-07-16T20:49:57.710-0700] {processor.py:841} WARNING - No viable dags retrieved from /Volumes/Personal Drive/GitHub/gdpr-ccpa-risk-pipeline/dags/gdpr_ccpa_risk_pipeline.py
[2025-07-16T20:50:00.194-0700] {processor.py:179} INFO - Processing /Volumes/Personal Drive/GitHub/gdpr-ccpa-risk-pipeline/dags/gdpr_ccpa_risk_pipeline.py took 3.527 seconds
[2025-07-16T20:51:04.734-0700] {processor.py:157} INFO - Started process (PID=12143) to work on /Volumes/Personal Drive/GitHub/gdpr-ccpa-risk-pipeline/dags/gdpr_ccpa_risk_pipeline.py
[2025-07-16T20:51:04.779-0700] {processor.py:829} INFO - Processing file /Volumes/Personal Drive/GitHub/gdpr-ccpa-risk-pipeline/dags/gdpr_ccpa_risk_pipeline.py for tasks to queue
[2025-07-16T20:51:04.779-0700] {logging_mixin.py:151} INFO - [2025-07-16T20:51:04.779-0700] {dagbag.py:539} INFO - Filling up the DagBag from /Volumes/Personal Drive/GitHub/gdpr-ccpa-risk-pipeline/dags/gdpr_ccpa_risk_pipeline.py
[2025-07-16T20:51:05.811-0700] {logging_mixin.py:151} INFO - [2025-07-16T20:51:05.792-0700] {dagbag.py:347} ERROR - Failed to import: /Volumes/Personal Drive/GitHub/gdpr-ccpa-risk-pipeline/dags/gdpr_ccpa_risk_pipeline.py
Traceback (most recent call last):
  File "/Volumes/Personal Drive/GitHub/gdpr-ccpa-risk-pipeline/venv/lib/python3.11/site-packages/airflow/models/dagbag.py", line 343, in parse
    loader.exec_module(new_module)
  File "<frozen importlib._bootstrap_external>", line 940, in exec_module
  File "<frozen importlib._bootstrap>", line 241, in _call_with_frames_removed
  File "/Volumes/Personal Drive/GitHub/gdpr-ccpa-risk-pipeline/dags/gdpr_ccpa_risk_pipeline.py", line 21, in <module>
    from scripts.fetch_policy_data      import fetch_policy_data
ModuleNotFoundError: No module named 'scripts'
[2025-07-16T20:51:05.829-0700] {processor.py:841} WARNING - No viable dags retrieved from /Volumes/Personal Drive/GitHub/gdpr-ccpa-risk-pipeline/dags/gdpr_ccpa_risk_pipeline.py
[2025-07-16T20:51:09.252-0700] {processor.py:179} INFO - Processing /Volumes/Personal Drive/GitHub/gdpr-ccpa-risk-pipeline/dags/gdpr_ccpa_risk_pipeline.py took 4.518 seconds
[2025-07-16T20:52:12.693-0700] {processor.py:157} INFO - Started process (PID=12183) to work on /Volumes/Personal Drive/GitHub/gdpr-ccpa-risk-pipeline/dags/gdpr_ccpa_risk_pipeline.py
[2025-07-16T20:52:12.747-0700] {processor.py:829} INFO - Processing file /Volumes/Personal Drive/GitHub/gdpr-ccpa-risk-pipeline/dags/gdpr_ccpa_risk_pipeline.py for tasks to queue
[2025-07-16T20:52:12.748-0700] {logging_mixin.py:151} INFO - [2025-07-16T20:52:12.747-0700] {dagbag.py:539} INFO - Filling up the DagBag from /Volumes/Personal Drive/GitHub/gdpr-ccpa-risk-pipeline/dags/gdpr_ccpa_risk_pipeline.py
[2025-07-16T20:52:13.664-0700] {logging_mixin.py:151} INFO - [2025-07-16T20:52:13.644-0700] {dagbag.py:347} ERROR - Failed to import: /Volumes/Personal Drive/GitHub/gdpr-ccpa-risk-pipeline/dags/gdpr_ccpa_risk_pipeline.py
Traceback (most recent call last):
  File "/Volumes/Personal Drive/GitHub/gdpr-ccpa-risk-pipeline/venv/lib/python3.11/site-packages/airflow/models/dagbag.py", line 343, in parse
    loader.exec_module(new_module)
  File "<frozen importlib._bootstrap_external>", line 940, in exec_module
  File "<frozen importlib._bootstrap>", line 241, in _call_with_frames_removed
  File "/Volumes/Personal Drive/GitHub/gdpr-ccpa-risk-pipeline/dags/gdpr_ccpa_risk_pipeline.py", line 21, in <module>
    from scripts.fetch_policy_data      import fetch_policy_data
ModuleNotFoundError: No module named 'scripts'
[2025-07-16T20:52:13.670-0700] {processor.py:841} WARNING - No viable dags retrieved from /Volumes/Personal Drive/GitHub/gdpr-ccpa-risk-pipeline/dags/gdpr_ccpa_risk_pipeline.py
[2025-07-16T20:52:16.513-0700] {processor.py:179} INFO - Processing /Volumes/Personal Drive/GitHub/gdpr-ccpa-risk-pipeline/dags/gdpr_ccpa_risk_pipeline.py took 3.846 seconds
[2025-07-16T20:53:20.852-0700] {processor.py:157} INFO - Started process (PID=12216) to work on /Volumes/Personal Drive/GitHub/gdpr-ccpa-risk-pipeline/dags/gdpr_ccpa_risk_pipeline.py
[2025-07-16T20:53:20.901-0700] {processor.py:829} INFO - Processing file /Volumes/Personal Drive/GitHub/gdpr-ccpa-risk-pipeline/dags/gdpr_ccpa_risk_pipeline.py for tasks to queue
[2025-07-16T20:53:20.901-0700] {logging_mixin.py:151} INFO - [2025-07-16T20:53:20.901-0700] {dagbag.py:539} INFO - Filling up the DagBag from /Volumes/Personal Drive/GitHub/gdpr-ccpa-risk-pipeline/dags/gdpr_ccpa_risk_pipeline.py
[2025-07-16T20:53:21.326-0700] {logging_mixin.py:151} INFO - [2025-07-16T20:53:21.301-0700] {dagbag.py:347} ERROR - Failed to import: /Volumes/Personal Drive/GitHub/gdpr-ccpa-risk-pipeline/dags/gdpr_ccpa_risk_pipeline.py
Traceback (most recent call last):
  File "/Volumes/Personal Drive/GitHub/gdpr-ccpa-risk-pipeline/venv/lib/python3.11/site-packages/airflow/models/dagbag.py", line 343, in parse
    loader.exec_module(new_module)
  File "<frozen importlib._bootstrap_external>", line 940, in exec_module
  File "<frozen importlib._bootstrap>", line 241, in _call_with_frames_removed
  File "/Volumes/Personal Drive/GitHub/gdpr-ccpa-risk-pipeline/dags/gdpr_ccpa_risk_pipeline.py", line 21, in <module>
    from scripts.fetch_policy_data      import fetch_policy_data
ModuleNotFoundError: No module named 'scripts'
[2025-07-16T20:53:21.327-0700] {processor.py:841} WARNING - No viable dags retrieved from /Volumes/Personal Drive/GitHub/gdpr-ccpa-risk-pipeline/dags/gdpr_ccpa_risk_pipeline.py
[2025-07-16T20:53:23.977-0700] {processor.py:179} INFO - Processing /Volumes/Personal Drive/GitHub/gdpr-ccpa-risk-pipeline/dags/gdpr_ccpa_risk_pipeline.py took 3.154 seconds
[2025-07-16T20:54:26.603-0700] {processor.py:157} INFO - Started process (PID=12251) to work on /Volumes/Personal Drive/GitHub/gdpr-ccpa-risk-pipeline/dags/gdpr_ccpa_risk_pipeline.py
[2025-07-16T20:54:26.667-0700] {processor.py:829} INFO - Processing file /Volumes/Personal Drive/GitHub/gdpr-ccpa-risk-pipeline/dags/gdpr_ccpa_risk_pipeline.py for tasks to queue
[2025-07-16T20:54:26.693-0700] {logging_mixin.py:151} INFO - [2025-07-16T20:54:26.680-0700] {dagbag.py:539} INFO - Filling up the DagBag from /Volumes/Personal Drive/GitHub/gdpr-ccpa-risk-pipeline/dags/gdpr_ccpa_risk_pipeline.py
[2025-07-16T20:54:27.584-0700] {logging_mixin.py:151} INFO - [2025-07-16T20:54:27.547-0700] {dagbag.py:347} ERROR - Failed to import: /Volumes/Personal Drive/GitHub/gdpr-ccpa-risk-pipeline/dags/gdpr_ccpa_risk_pipeline.py
Traceback (most recent call last):
  File "/Volumes/Personal Drive/GitHub/gdpr-ccpa-risk-pipeline/venv/lib/python3.11/site-packages/airflow/models/dagbag.py", line 343, in parse
    loader.exec_module(new_module)
  File "<frozen importlib._bootstrap_external>", line 940, in exec_module
  File "<frozen importlib._bootstrap>", line 241, in _call_with_frames_removed
  File "/Volumes/Personal Drive/GitHub/gdpr-ccpa-risk-pipeline/dags/gdpr_ccpa_risk_pipeline.py", line 21, in <module>
    from scripts.fetch_policy_data      import fetch_policy_data
ModuleNotFoundError: No module named 'scripts'
[2025-07-16T20:54:27.590-0700] {processor.py:841} WARNING - No viable dags retrieved from /Volumes/Personal Drive/GitHub/gdpr-ccpa-risk-pipeline/dags/gdpr_ccpa_risk_pipeline.py
[2025-07-16T20:54:29.585-0700] {processor.py:179} INFO - Processing /Volumes/Personal Drive/GitHub/gdpr-ccpa-risk-pipeline/dags/gdpr_ccpa_risk_pipeline.py took 3.010 seconds
[2025-07-16T20:55:41.209-0700] {processor.py:157} INFO - Started process (PID=12283) to work on /Volumes/Personal Drive/GitHub/gdpr-ccpa-risk-pipeline/dags/gdpr_ccpa_risk_pipeline.py
[2025-07-16T20:55:41.289-0700] {processor.py:829} INFO - Processing file /Volumes/Personal Drive/GitHub/gdpr-ccpa-risk-pipeline/dags/gdpr_ccpa_risk_pipeline.py for tasks to queue
[2025-07-16T20:55:41.325-0700] {logging_mixin.py:151} INFO - [2025-07-16T20:55:41.324-0700] {dagbag.py:539} INFO - Filling up the DagBag from /Volumes/Personal Drive/GitHub/gdpr-ccpa-risk-pipeline/dags/gdpr_ccpa_risk_pipeline.py
[2025-07-16T20:55:42.657-0700] {logging_mixin.py:151} INFO - [2025-07-16T20:55:42.584-0700] {dagbag.py:347} ERROR - Failed to import: /Volumes/Personal Drive/GitHub/gdpr-ccpa-risk-pipeline/dags/gdpr_ccpa_risk_pipeline.py
Traceback (most recent call last):
  File "/Volumes/Personal Drive/GitHub/gdpr-ccpa-risk-pipeline/venv/lib/python3.11/site-packages/airflow/models/dagbag.py", line 343, in parse
    loader.exec_module(new_module)
  File "<frozen importlib._bootstrap_external>", line 940, in exec_module
  File "<frozen importlib._bootstrap>", line 241, in _call_with_frames_removed
  File "/Volumes/Personal Drive/GitHub/gdpr-ccpa-risk-pipeline/dags/gdpr_ccpa_risk_pipeline.py", line 21, in <module>
    from scripts.fetch_policy_data      import fetch_policy_data
ModuleNotFoundError: No module named 'scripts'
[2025-07-16T20:55:42.660-0700] {processor.py:841} WARNING - No viable dags retrieved from /Volumes/Personal Drive/GitHub/gdpr-ccpa-risk-pipeline/dags/gdpr_ccpa_risk_pipeline.py
[2025-07-16T20:55:45.870-0700] {processor.py:179} INFO - Processing /Volumes/Personal Drive/GitHub/gdpr-ccpa-risk-pipeline/dags/gdpr_ccpa_risk_pipeline.py took 4.687 seconds
[2025-07-16T20:56:58.104-0700] {processor.py:157} INFO - Started process (PID=12321) to work on /Volumes/Personal Drive/GitHub/gdpr-ccpa-risk-pipeline/dags/gdpr_ccpa_risk_pipeline.py
[2025-07-16T20:56:58.106-0700] {processor.py:829} INFO - Processing file /Volumes/Personal Drive/GitHub/gdpr-ccpa-risk-pipeline/dags/gdpr_ccpa_risk_pipeline.py for tasks to queue
[2025-07-16T20:56:58.147-0700] {logging_mixin.py:151} INFO - [2025-07-16T20:56:58.141-0700] {dagbag.py:539} INFO - Filling up the DagBag from /Volumes/Personal Drive/GitHub/gdpr-ccpa-risk-pipeline/dags/gdpr_ccpa_risk_pipeline.py
[2025-07-16T20:56:59.597-0700] {logging_mixin.py:151} INFO - [2025-07-16T20:56:59.573-0700] {dagbag.py:347} ERROR - Failed to import: /Volumes/Personal Drive/GitHub/gdpr-ccpa-risk-pipeline/dags/gdpr_ccpa_risk_pipeline.py
Traceback (most recent call last):
  File "/Volumes/Personal Drive/GitHub/gdpr-ccpa-risk-pipeline/venv/lib/python3.11/site-packages/airflow/models/dagbag.py", line 343, in parse
    loader.exec_module(new_module)
  File "<frozen importlib._bootstrap_external>", line 940, in exec_module
  File "<frozen importlib._bootstrap>", line 241, in _call_with_frames_removed
  File "/Volumes/Personal Drive/GitHub/gdpr-ccpa-risk-pipeline/dags/gdpr_ccpa_risk_pipeline.py", line 21, in <module>
    from scripts.fetch_policy_data      import fetch_policy_data
ModuleNotFoundError: No module named 'scripts'
[2025-07-16T20:56:59.610-0700] {processor.py:841} WARNING - No viable dags retrieved from /Volumes/Personal Drive/GitHub/gdpr-ccpa-risk-pipeline/dags/gdpr_ccpa_risk_pipeline.py
[2025-07-16T20:57:03.139-0700] {processor.py:179} INFO - Processing /Volumes/Personal Drive/GitHub/gdpr-ccpa-risk-pipeline/dags/gdpr_ccpa_risk_pipeline.py took 5.065 seconds
[2025-07-16T20:58:11.335-0700] {processor.py:157} INFO - Started process (PID=12360) to work on /Volumes/Personal Drive/GitHub/gdpr-ccpa-risk-pipeline/dags/gdpr_ccpa_risk_pipeline.py
[2025-07-16T20:58:11.442-0700] {processor.py:829} INFO - Processing file /Volumes/Personal Drive/GitHub/gdpr-ccpa-risk-pipeline/dags/gdpr_ccpa_risk_pipeline.py for tasks to queue
[2025-07-16T20:58:11.521-0700] {logging_mixin.py:151} INFO - [2025-07-16T20:58:11.500-0700] {dagbag.py:539} INFO - Filling up the DagBag from /Volumes/Personal Drive/GitHub/gdpr-ccpa-risk-pipeline/dags/gdpr_ccpa_risk_pipeline.py
[2025-07-16T20:58:12.747-0700] {logging_mixin.py:151} INFO - [2025-07-16T20:58:12.717-0700] {dagbag.py:347} ERROR - Failed to import: /Volumes/Personal Drive/GitHub/gdpr-ccpa-risk-pipeline/dags/gdpr_ccpa_risk_pipeline.py
Traceback (most recent call last):
  File "/Volumes/Personal Drive/GitHub/gdpr-ccpa-risk-pipeline/venv/lib/python3.11/site-packages/airflow/models/dagbag.py", line 343, in parse
    loader.exec_module(new_module)
  File "<frozen importlib._bootstrap_external>", line 940, in exec_module
  File "<frozen importlib._bootstrap>", line 241, in _call_with_frames_removed
  File "/Volumes/Personal Drive/GitHub/gdpr-ccpa-risk-pipeline/dags/gdpr_ccpa_risk_pipeline.py", line 21, in <module>
    from scripts.fetch_policy_data      import fetch_policy_data
ModuleNotFoundError: No module named 'scripts'
[2025-07-16T20:58:12.755-0700] {processor.py:841} WARNING - No viable dags retrieved from /Volumes/Personal Drive/GitHub/gdpr-ccpa-risk-pipeline/dags/gdpr_ccpa_risk_pipeline.py
[2025-07-16T20:58:16.379-0700] {processor.py:179} INFO - Processing /Volumes/Personal Drive/GitHub/gdpr-ccpa-risk-pipeline/dags/gdpr_ccpa_risk_pipeline.py took 5.053 seconds
[2025-07-16T20:59:22.600-0700] {processor.py:157} INFO - Started process (PID=12398) to work on /Volumes/Personal Drive/GitHub/gdpr-ccpa-risk-pipeline/dags/gdpr_ccpa_risk_pipeline.py
[2025-07-16T20:59:22.648-0700] {processor.py:829} INFO - Processing file /Volumes/Personal Drive/GitHub/gdpr-ccpa-risk-pipeline/dags/gdpr_ccpa_risk_pipeline.py for tasks to queue
[2025-07-16T20:59:22.649-0700] {logging_mixin.py:151} INFO - [2025-07-16T20:59:22.649-0700] {dagbag.py:539} INFO - Filling up the DagBag from /Volumes/Personal Drive/GitHub/gdpr-ccpa-risk-pipeline/dags/gdpr_ccpa_risk_pipeline.py
[2025-07-16T20:59:23.790-0700] {logging_mixin.py:151} INFO - [2025-07-16T20:59:23.750-0700] {dagbag.py:347} ERROR - Failed to import: /Volumes/Personal Drive/GitHub/gdpr-ccpa-risk-pipeline/dags/gdpr_ccpa_risk_pipeline.py
Traceback (most recent call last):
  File "/Volumes/Personal Drive/GitHub/gdpr-ccpa-risk-pipeline/venv/lib/python3.11/site-packages/airflow/models/dagbag.py", line 343, in parse
    loader.exec_module(new_module)
  File "<frozen importlib._bootstrap_external>", line 940, in exec_module
  File "<frozen importlib._bootstrap>", line 241, in _call_with_frames_removed
  File "/Volumes/Personal Drive/GitHub/gdpr-ccpa-risk-pipeline/dags/gdpr_ccpa_risk_pipeline.py", line 21, in <module>
    from scripts.fetch_policy_data      import fetch_policy_data
ModuleNotFoundError: No module named 'scripts'
[2025-07-16T20:59:23.792-0700] {processor.py:841} WARNING - No viable dags retrieved from /Volumes/Personal Drive/GitHub/gdpr-ccpa-risk-pipeline/dags/gdpr_ccpa_risk_pipeline.py
[2025-07-16T20:59:26.656-0700] {processor.py:179} INFO - Processing /Volumes/Personal Drive/GitHub/gdpr-ccpa-risk-pipeline/dags/gdpr_ccpa_risk_pipeline.py took 4.072 seconds
[2025-07-16T21:00:35.470-0700] {processor.py:157} INFO - Started process (PID=12424) to work on /Volumes/Personal Drive/GitHub/gdpr-ccpa-risk-pipeline/dags/gdpr_ccpa_risk_pipeline.py
[2025-07-16T21:00:35.509-0700] {processor.py:829} INFO - Processing file /Volumes/Personal Drive/GitHub/gdpr-ccpa-risk-pipeline/dags/gdpr_ccpa_risk_pipeline.py for tasks to queue
[2025-07-16T21:00:35.563-0700] {logging_mixin.py:151} INFO - [2025-07-16T21:00:35.542-0700] {dagbag.py:539} INFO - Filling up the DagBag from /Volumes/Personal Drive/GitHub/gdpr-ccpa-risk-pipeline/dags/gdpr_ccpa_risk_pipeline.py
[2025-07-16T21:00:36.459-0700] {logging_mixin.py:151} INFO - [2025-07-16T21:00:36.444-0700] {dagbag.py:347} ERROR - Failed to import: /Volumes/Personal Drive/GitHub/gdpr-ccpa-risk-pipeline/dags/gdpr_ccpa_risk_pipeline.py
Traceback (most recent call last):
  File "/Volumes/Personal Drive/GitHub/gdpr-ccpa-risk-pipeline/venv/lib/python3.11/site-packages/airflow/models/dagbag.py", line 343, in parse
    loader.exec_module(new_module)
  File "<frozen importlib._bootstrap_external>", line 940, in exec_module
  File "<frozen importlib._bootstrap>", line 241, in _call_with_frames_removed
  File "/Volumes/Personal Drive/GitHub/gdpr-ccpa-risk-pipeline/dags/gdpr_ccpa_risk_pipeline.py", line 21, in <module>
    from scripts.fetch_policy_data      import fetch_policy_data
ModuleNotFoundError: No module named 'scripts'
[2025-07-16T21:00:36.493-0700] {processor.py:841} WARNING - No viable dags retrieved from /Volumes/Personal Drive/GitHub/gdpr-ccpa-risk-pipeline/dags/gdpr_ccpa_risk_pipeline.py
[2025-07-16T21:00:39.871-0700] {processor.py:179} INFO - Processing /Volumes/Personal Drive/GitHub/gdpr-ccpa-risk-pipeline/dags/gdpr_ccpa_risk_pipeline.py took 4.435 seconds
[2025-07-16T21:01:48.673-0700] {processor.py:157} INFO - Started process (PID=12456) to work on /Volumes/Personal Drive/GitHub/gdpr-ccpa-risk-pipeline/dags/gdpr_ccpa_risk_pipeline.py
[2025-07-16T21:01:48.740-0700] {processor.py:829} INFO - Processing file /Volumes/Personal Drive/GitHub/gdpr-ccpa-risk-pipeline/dags/gdpr_ccpa_risk_pipeline.py for tasks to queue
[2025-07-16T21:01:48.773-0700] {logging_mixin.py:151} INFO - [2025-07-16T21:01:48.773-0700] {dagbag.py:539} INFO - Filling up the DagBag from /Volumes/Personal Drive/GitHub/gdpr-ccpa-risk-pipeline/dags/gdpr_ccpa_risk_pipeline.py
[2025-07-16T21:01:49.628-0700] {logging_mixin.py:151} INFO - [2025-07-16T21:01:49.565-0700] {dagbag.py:347} ERROR - Failed to import: /Volumes/Personal Drive/GitHub/gdpr-ccpa-risk-pipeline/dags/gdpr_ccpa_risk_pipeline.py
Traceback (most recent call last):
  File "/Volumes/Personal Drive/GitHub/gdpr-ccpa-risk-pipeline/venv/lib/python3.11/site-packages/airflow/models/dagbag.py", line 343, in parse
    loader.exec_module(new_module)
  File "<frozen importlib._bootstrap_external>", line 940, in exec_module
  File "<frozen importlib._bootstrap>", line 241, in _call_with_frames_removed
  File "/Volumes/Personal Drive/GitHub/gdpr-ccpa-risk-pipeline/dags/gdpr_ccpa_risk_pipeline.py", line 21, in <module>
    from scripts.fetch_policy_data      import fetch_policy_data
ModuleNotFoundError: No module named 'scripts'
[2025-07-16T21:01:49.637-0700] {processor.py:841} WARNING - No viable dags retrieved from /Volumes/Personal Drive/GitHub/gdpr-ccpa-risk-pipeline/dags/gdpr_ccpa_risk_pipeline.py
[2025-07-16T21:01:53.263-0700] {processor.py:179} INFO - Processing /Volumes/Personal Drive/GitHub/gdpr-ccpa-risk-pipeline/dags/gdpr_ccpa_risk_pipeline.py took 4.592 seconds
[2025-07-16T21:03:03.319-0700] {processor.py:157} INFO - Started process (PID=12491) to work on /Volumes/Personal Drive/GitHub/gdpr-ccpa-risk-pipeline/dags/gdpr_ccpa_risk_pipeline.py
[2025-07-16T21:03:03.380-0700] {processor.py:829} INFO - Processing file /Volumes/Personal Drive/GitHub/gdpr-ccpa-risk-pipeline/dags/gdpr_ccpa_risk_pipeline.py for tasks to queue
[2025-07-16T21:03:03.380-0700] {logging_mixin.py:151} INFO - [2025-07-16T21:03:03.380-0700] {dagbag.py:539} INFO - Filling up the DagBag from /Volumes/Personal Drive/GitHub/gdpr-ccpa-risk-pipeline/dags/gdpr_ccpa_risk_pipeline.py
[2025-07-16T21:03:04.332-0700] {logging_mixin.py:151} INFO - [2025-07-16T21:03:04.300-0700] {dagbag.py:347} ERROR - Failed to import: /Volumes/Personal Drive/GitHub/gdpr-ccpa-risk-pipeline/dags/gdpr_ccpa_risk_pipeline.py
Traceback (most recent call last):
  File "/Volumes/Personal Drive/GitHub/gdpr-ccpa-risk-pipeline/venv/lib/python3.11/site-packages/airflow/models/dagbag.py", line 343, in parse
    loader.exec_module(new_module)
  File "<frozen importlib._bootstrap_external>", line 940, in exec_module
  File "<frozen importlib._bootstrap>", line 241, in _call_with_frames_removed
  File "/Volumes/Personal Drive/GitHub/gdpr-ccpa-risk-pipeline/dags/gdpr_ccpa_risk_pipeline.py", line 21, in <module>
    from scripts.fetch_policy_data      import fetch_policy_data
ModuleNotFoundError: No module named 'scripts'
[2025-07-16T21:03:04.334-0700] {processor.py:841} WARNING - No viable dags retrieved from /Volumes/Personal Drive/GitHub/gdpr-ccpa-risk-pipeline/dags/gdpr_ccpa_risk_pipeline.py
[2025-07-16T21:03:07.935-0700] {processor.py:179} INFO - Processing /Volumes/Personal Drive/GitHub/gdpr-ccpa-risk-pipeline/dags/gdpr_ccpa_risk_pipeline.py took 4.639 seconds
[2025-07-16T21:04:15.909-0700] {processor.py:157} INFO - Started process (PID=12523) to work on /Volumes/Personal Drive/GitHub/gdpr-ccpa-risk-pipeline/dags/gdpr_ccpa_risk_pipeline.py
[2025-07-16T21:04:15.940-0700] {processor.py:829} INFO - Processing file /Volumes/Personal Drive/GitHub/gdpr-ccpa-risk-pipeline/dags/gdpr_ccpa_risk_pipeline.py for tasks to queue
[2025-07-16T21:04:15.943-0700] {logging_mixin.py:151} INFO - [2025-07-16T21:04:15.943-0700] {dagbag.py:539} INFO - Filling up the DagBag from /Volumes/Personal Drive/GitHub/gdpr-ccpa-risk-pipeline/dags/gdpr_ccpa_risk_pipeline.py
[2025-07-16T21:04:16.660-0700] {logging_mixin.py:151} INFO - [2025-07-16T21:04:16.604-0700] {dagbag.py:347} ERROR - Failed to import: /Volumes/Personal Drive/GitHub/gdpr-ccpa-risk-pipeline/dags/gdpr_ccpa_risk_pipeline.py
Traceback (most recent call last):
  File "/Volumes/Personal Drive/GitHub/gdpr-ccpa-risk-pipeline/venv/lib/python3.11/site-packages/airflow/models/dagbag.py", line 343, in parse
    loader.exec_module(new_module)
  File "<frozen importlib._bootstrap_external>", line 940, in exec_module
  File "<frozen importlib._bootstrap>", line 241, in _call_with_frames_removed
  File "/Volumes/Personal Drive/GitHub/gdpr-ccpa-risk-pipeline/dags/gdpr_ccpa_risk_pipeline.py", line 21, in <module>
    from scripts.fetch_policy_data      import fetch_policy_data
ModuleNotFoundError: No module named 'scripts'
[2025-07-16T21:04:16.677-0700] {processor.py:841} WARNING - No viable dags retrieved from /Volumes/Personal Drive/GitHub/gdpr-ccpa-risk-pipeline/dags/gdpr_ccpa_risk_pipeline.py
[2025-07-16T21:04:20.867-0700] {processor.py:179} INFO - Processing /Volumes/Personal Drive/GitHub/gdpr-ccpa-risk-pipeline/dags/gdpr_ccpa_risk_pipeline.py took 5.008 seconds
[2025-07-16T21:05:19.748-0700] {processor.py:157} INFO - Started process (PID=12562) to work on /Volumes/Personal Drive/GitHub/gdpr-ccpa-risk-pipeline/dags/gdpr_ccpa_risk_pipeline.py
[2025-07-16T21:05:19.787-0700] {processor.py:829} INFO - Processing file /Volumes/Personal Drive/GitHub/gdpr-ccpa-risk-pipeline/dags/gdpr_ccpa_risk_pipeline.py for tasks to queue
[2025-07-16T21:05:19.796-0700] {logging_mixin.py:151} INFO - [2025-07-16T21:05:19.796-0700] {dagbag.py:539} INFO - Filling up the DagBag from /Volumes/Personal Drive/GitHub/gdpr-ccpa-risk-pipeline/dags/gdpr_ccpa_risk_pipeline.py
[2025-07-16T21:05:20.072-0700] {logging_mixin.py:151} INFO - [2025-07-16T21:05:20.047-0700] {dagbag.py:347} ERROR - Failed to import: /Volumes/Personal Drive/GitHub/gdpr-ccpa-risk-pipeline/dags/gdpr_ccpa_risk_pipeline.py
Traceback (most recent call last):
  File "/Volumes/Personal Drive/GitHub/gdpr-ccpa-risk-pipeline/venv/lib/python3.11/site-packages/airflow/models/dagbag.py", line 343, in parse
    loader.exec_module(new_module)
  File "<frozen importlib._bootstrap_external>", line 940, in exec_module
  File "<frozen importlib._bootstrap>", line 241, in _call_with_frames_removed
  File "/Volumes/Personal Drive/GitHub/gdpr-ccpa-risk-pipeline/dags/gdpr_ccpa_risk_pipeline.py", line 21, in <module>
    from scripts.fetch_policy_data      import fetch_policy_data
ModuleNotFoundError: No module named 'scripts'
[2025-07-16T21:05:20.074-0700] {processor.py:841} WARNING - No viable dags retrieved from /Volumes/Personal Drive/GitHub/gdpr-ccpa-risk-pipeline/dags/gdpr_ccpa_risk_pipeline.py
[2025-07-16T21:05:20.937-0700] {processor.py:179} INFO - Processing /Volumes/Personal Drive/GitHub/gdpr-ccpa-risk-pipeline/dags/gdpr_ccpa_risk_pipeline.py took 1.193 seconds
[2025-07-16T21:06:09.232-0700] {processor.py:157} INFO - Started process (PID=12602) to work on /Volumes/Personal Drive/GitHub/gdpr-ccpa-risk-pipeline/dags/gdpr_ccpa_risk_pipeline.py
[2025-07-16T21:06:09.285-0700] {processor.py:829} INFO - Processing file /Volumes/Personal Drive/GitHub/gdpr-ccpa-risk-pipeline/dags/gdpr_ccpa_risk_pipeline.py for tasks to queue
[2025-07-16T21:06:09.288-0700] {logging_mixin.py:151} INFO - [2025-07-16T21:06:09.288-0700] {dagbag.py:539} INFO - Filling up the DagBag from /Volumes/Personal Drive/GitHub/gdpr-ccpa-risk-pipeline/dags/gdpr_ccpa_risk_pipeline.py
[2025-07-16T21:06:09.714-0700] {logging_mixin.py:151} INFO - [2025-07-16T21:06:09.695-0700] {dagbag.py:347} ERROR - Failed to import: /Volumes/Personal Drive/GitHub/gdpr-ccpa-risk-pipeline/dags/gdpr_ccpa_risk_pipeline.py
Traceback (most recent call last):
  File "/Volumes/Personal Drive/GitHub/gdpr-ccpa-risk-pipeline/venv/lib/python3.11/site-packages/airflow/models/dagbag.py", line 343, in parse
    loader.exec_module(new_module)
  File "<frozen importlib._bootstrap_external>", line 940, in exec_module
  File "<frozen importlib._bootstrap>", line 241, in _call_with_frames_removed
  File "/Volumes/Personal Drive/GitHub/gdpr-ccpa-risk-pipeline/dags/gdpr_ccpa_risk_pipeline.py", line 21, in <module>
    from scripts.fetch_policy_data      import fetch_policy_data
ModuleNotFoundError: No module named 'scripts'
[2025-07-16T21:06:09.716-0700] {processor.py:841} WARNING - No viable dags retrieved from /Volumes/Personal Drive/GitHub/gdpr-ccpa-risk-pipeline/dags/gdpr_ccpa_risk_pipeline.py
[2025-07-16T21:06:10.531-0700] {processor.py:179} INFO - Processing /Volumes/Personal Drive/GitHub/gdpr-ccpa-risk-pipeline/dags/gdpr_ccpa_risk_pipeline.py took 1.305 seconds
[2025-07-16T21:06:55.049-0700] {processor.py:157} INFO - Started process (PID=12651) to work on /Volumes/Personal Drive/GitHub/gdpr-ccpa-risk-pipeline/dags/gdpr_ccpa_risk_pipeline.py
[2025-07-16T21:06:55.068-0700] {processor.py:829} INFO - Processing file /Volumes/Personal Drive/GitHub/gdpr-ccpa-risk-pipeline/dags/gdpr_ccpa_risk_pipeline.py for tasks to queue
[2025-07-16T21:06:55.070-0700] {logging_mixin.py:151} INFO - [2025-07-16T21:06:55.070-0700] {dagbag.py:539} INFO - Filling up the DagBag from /Volumes/Personal Drive/GitHub/gdpr-ccpa-risk-pipeline/dags/gdpr_ccpa_risk_pipeline.py
[2025-07-16T21:06:55.524-0700] {logging_mixin.py:151} INFO - [2025-07-16T21:06:55.515-0700] {dagbag.py:347} ERROR - Failed to import: /Volumes/Personal Drive/GitHub/gdpr-ccpa-risk-pipeline/dags/gdpr_ccpa_risk_pipeline.py
Traceback (most recent call last):
  File "/Volumes/Personal Drive/GitHub/gdpr-ccpa-risk-pipeline/venv/lib/python3.11/site-packages/airflow/models/dagbag.py", line 343, in parse
    loader.exec_module(new_module)
  File "<frozen importlib._bootstrap_external>", line 940, in exec_module
  File "<frozen importlib._bootstrap>", line 241, in _call_with_frames_removed
  File "/Volumes/Personal Drive/GitHub/gdpr-ccpa-risk-pipeline/dags/gdpr_ccpa_risk_pipeline.py", line 21, in <module>
    from scripts.fetch_policy_data      import fetch_policy_data
ModuleNotFoundError: No module named 'scripts'
[2025-07-16T21:06:55.527-0700] {processor.py:841} WARNING - No viable dags retrieved from /Volumes/Personal Drive/GitHub/gdpr-ccpa-risk-pipeline/dags/gdpr_ccpa_risk_pipeline.py
[2025-07-16T21:06:56.400-0700] {processor.py:179} INFO - Processing /Volumes/Personal Drive/GitHub/gdpr-ccpa-risk-pipeline/dags/gdpr_ccpa_risk_pipeline.py took 1.376 seconds
[2025-07-16T21:07:44.303-0700] {processor.py:157} INFO - Started process (PID=12689) to work on /Volumes/Personal Drive/GitHub/gdpr-ccpa-risk-pipeline/dags/gdpr_ccpa_risk_pipeline.py
[2025-07-16T21:07:44.304-0700] {processor.py:829} INFO - Processing file /Volumes/Personal Drive/GitHub/gdpr-ccpa-risk-pipeline/dags/gdpr_ccpa_risk_pipeline.py for tasks to queue
[2025-07-16T21:07:44.305-0700] {logging_mixin.py:151} INFO - [2025-07-16T21:07:44.305-0700] {dagbag.py:539} INFO - Filling up the DagBag from /Volumes/Personal Drive/GitHub/gdpr-ccpa-risk-pipeline/dags/gdpr_ccpa_risk_pipeline.py
[2025-07-16T21:07:44.487-0700] {logging_mixin.py:151} INFO - [2025-07-16T21:07:44.483-0700] {dagbag.py:347} ERROR - Failed to import: /Volumes/Personal Drive/GitHub/gdpr-ccpa-risk-pipeline/dags/gdpr_ccpa_risk_pipeline.py
Traceback (most recent call last):
  File "/Volumes/Personal Drive/GitHub/gdpr-ccpa-risk-pipeline/venv/lib/python3.11/site-packages/airflow/models/dagbag.py", line 343, in parse
    loader.exec_module(new_module)
  File "<frozen importlib._bootstrap_external>", line 940, in exec_module
  File "<frozen importlib._bootstrap>", line 241, in _call_with_frames_removed
  File "/Volumes/Personal Drive/GitHub/gdpr-ccpa-risk-pipeline/dags/gdpr_ccpa_risk_pipeline.py", line 21, in <module>
    from scripts.fetch_policy_data      import fetch_policy_data
ModuleNotFoundError: No module named 'scripts'
[2025-07-16T21:07:44.488-0700] {processor.py:841} WARNING - No viable dags retrieved from /Volumes/Personal Drive/GitHub/gdpr-ccpa-risk-pipeline/dags/gdpr_ccpa_risk_pipeline.py
[2025-07-16T21:07:44.977-0700] {processor.py:179} INFO - Processing /Volumes/Personal Drive/GitHub/gdpr-ccpa-risk-pipeline/dags/gdpr_ccpa_risk_pipeline.py took 0.690 seconds
[2025-07-16T21:08:22.841-0700] {processor.py:157} INFO - Started process (PID=12735) to work on /Volumes/Personal Drive/GitHub/gdpr-ccpa-risk-pipeline/dags/gdpr_ccpa_risk_pipeline.py
[2025-07-16T21:08:22.841-0700] {processor.py:829} INFO - Processing file /Volumes/Personal Drive/GitHub/gdpr-ccpa-risk-pipeline/dags/gdpr_ccpa_risk_pipeline.py for tasks to queue
[2025-07-16T21:08:22.857-0700] {logging_mixin.py:151} INFO - [2025-07-16T21:08:22.857-0700] {dagbag.py:539} INFO - Filling up the DagBag from /Volumes/Personal Drive/GitHub/gdpr-ccpa-risk-pipeline/dags/gdpr_ccpa_risk_pipeline.py
[2025-07-16T21:08:22.997-0700] {logging_mixin.py:151} INFO - [2025-07-16T21:08:22.996-0700] {dagbag.py:347} ERROR - Failed to import: /Volumes/Personal Drive/GitHub/gdpr-ccpa-risk-pipeline/dags/gdpr_ccpa_risk_pipeline.py
Traceback (most recent call last):
  File "/Volumes/Personal Drive/GitHub/gdpr-ccpa-risk-pipeline/venv/lib/python3.11/site-packages/airflow/models/dagbag.py", line 343, in parse
    loader.exec_module(new_module)
  File "<frozen importlib._bootstrap_external>", line 940, in exec_module
  File "<frozen importlib._bootstrap>", line 241, in _call_with_frames_removed
  File "/Volumes/Personal Drive/GitHub/gdpr-ccpa-risk-pipeline/dags/gdpr_ccpa_risk_pipeline.py", line 21, in <module>
    from scripts.fetch_policy_data      import fetch_policy_data
ModuleNotFoundError: No module named 'scripts'
[2025-07-16T21:08:23.030-0700] {processor.py:841} WARNING - No viable dags retrieved from /Volumes/Personal Drive/GitHub/gdpr-ccpa-risk-pipeline/dags/gdpr_ccpa_risk_pipeline.py
[2025-07-16T21:08:23.587-0700] {processor.py:179} INFO - Processing /Volumes/Personal Drive/GitHub/gdpr-ccpa-risk-pipeline/dags/gdpr_ccpa_risk_pipeline.py took 0.747 seconds
[2025-07-16T21:09:04.864-0700] {processor.py:157} INFO - Started process (PID=12765) to work on /Volumes/Personal Drive/GitHub/gdpr-ccpa-risk-pipeline/dags/gdpr_ccpa_risk_pipeline.py
[2025-07-16T21:09:04.879-0700] {processor.py:829} INFO - Processing file /Volumes/Personal Drive/GitHub/gdpr-ccpa-risk-pipeline/dags/gdpr_ccpa_risk_pipeline.py for tasks to queue
[2025-07-16T21:09:04.879-0700] {logging_mixin.py:151} INFO - [2025-07-16T21:09:04.879-0700] {dagbag.py:539} INFO - Filling up the DagBag from /Volumes/Personal Drive/GitHub/gdpr-ccpa-risk-pipeline/dags/gdpr_ccpa_risk_pipeline.py
[2025-07-16T21:09:05.171-0700] {logging_mixin.py:151} INFO - [2025-07-16T21:09:05.165-0700] {dagbag.py:347} ERROR - Failed to import: /Volumes/Personal Drive/GitHub/gdpr-ccpa-risk-pipeline/dags/gdpr_ccpa_risk_pipeline.py
Traceback (most recent call last):
  File "/Volumes/Personal Drive/GitHub/gdpr-ccpa-risk-pipeline/venv/lib/python3.11/site-packages/airflow/models/dagbag.py", line 343, in parse
    loader.exec_module(new_module)
  File "<frozen importlib._bootstrap_external>", line 940, in exec_module
  File "<frozen importlib._bootstrap>", line 241, in _call_with_frames_removed
  File "/Volumes/Personal Drive/GitHub/gdpr-ccpa-risk-pipeline/dags/gdpr_ccpa_risk_pipeline.py", line 21, in <module>
    from scripts.fetch_policy_data      import fetch_policy_data
ModuleNotFoundError: No module named 'scripts'
[2025-07-16T21:09:05.174-0700] {processor.py:841} WARNING - No viable dags retrieved from /Volumes/Personal Drive/GitHub/gdpr-ccpa-risk-pipeline/dags/gdpr_ccpa_risk_pipeline.py
[2025-07-16T21:09:05.863-0700] {processor.py:179} INFO - Processing /Volumes/Personal Drive/GitHub/gdpr-ccpa-risk-pipeline/dags/gdpr_ccpa_risk_pipeline.py took 1.001 seconds
[2025-07-16T21:09:33.157-0700] {processor.py:157} INFO - Started process (PID=12781) to work on /Volumes/Personal Drive/GitHub/gdpr-ccpa-risk-pipeline/dags/gdpr_ccpa_risk_pipeline.py
[2025-07-16T21:09:33.163-0700] {processor.py:829} INFO - Processing file /Volumes/Personal Drive/GitHub/gdpr-ccpa-risk-pipeline/dags/gdpr_ccpa_risk_pipeline.py for tasks to queue
[2025-07-16T21:09:33.167-0700] {logging_mixin.py:151} INFO - [2025-07-16T21:09:33.163-0700] {dagbag.py:539} INFO - Filling up the DagBag from /Volumes/Personal Drive/GitHub/gdpr-ccpa-risk-pipeline/dags/gdpr_ccpa_risk_pipeline.py
[2025-07-16T21:09:38.562-0700] {logging_mixin.py:151} INFO - [2025-07-16T21:09:38.559-0700] {dagbag.py:347} ERROR - Failed to import: /Volumes/Personal Drive/GitHub/gdpr-ccpa-risk-pipeline/dags/gdpr_ccpa_risk_pipeline.py
Traceback (most recent call last):
  File "/Volumes/Personal Drive/GitHub/gdpr-ccpa-risk-pipeline/venv/lib/python3.11/site-packages/airflow/models/dagbag.py", line 343, in parse
    loader.exec_module(new_module)
  File "<frozen importlib._bootstrap_external>", line 940, in exec_module
  File "<frozen importlib._bootstrap>", line 241, in _call_with_frames_removed
  File "/Volumes/Personal Drive/GitHub/gdpr-ccpa-risk-pipeline/dags/gdpr_ccpa_risk_pipeline.py", line 42, in <module>
    with DAG(
         ^^^^
TypeError: DAG.__init__() got an unexpected keyword argument 'load_examples'
[2025-07-16T21:09:38.565-0700] {processor.py:841} WARNING - No viable dags retrieved from /Volumes/Personal Drive/GitHub/gdpr-ccpa-risk-pipeline/dags/gdpr_ccpa_risk_pipeline.py
[2025-07-16T21:09:39.003-0700] {processor.py:179} INFO - Processing /Volumes/Personal Drive/GitHub/gdpr-ccpa-risk-pipeline/dags/gdpr_ccpa_risk_pipeline.py took 5.848 seconds
[2025-07-16T21:09:58.517-0700] {processor.py:157} INFO - Started process (PID=12793) to work on /Volumes/Personal Drive/GitHub/gdpr-ccpa-risk-pipeline/dags/gdpr_ccpa_risk_pipeline.py
[2025-07-16T21:09:58.521-0700] {processor.py:829} INFO - Processing file /Volumes/Personal Drive/GitHub/gdpr-ccpa-risk-pipeline/dags/gdpr_ccpa_risk_pipeline.py for tasks to queue
[2025-07-16T21:09:58.533-0700] {logging_mixin.py:151} INFO - [2025-07-16T21:09:58.533-0700] {dagbag.py:539} INFO - Filling up the DagBag from /Volumes/Personal Drive/GitHub/gdpr-ccpa-risk-pipeline/dags/gdpr_ccpa_risk_pipeline.py
[2025-07-16T21:10:01.596-0700] {logging_mixin.py:151} INFO - [2025-07-16T21:10:01.595-0700] {dagbag.py:347} ERROR - Failed to import: /Volumes/Personal Drive/GitHub/gdpr-ccpa-risk-pipeline/dags/gdpr_ccpa_risk_pipeline.py
Traceback (most recent call last):
  File "/Volumes/Personal Drive/GitHub/gdpr-ccpa-risk-pipeline/venv/lib/python3.11/site-packages/airflow/models/dagbag.py", line 343, in parse
    loader.exec_module(new_module)
  File "<frozen importlib._bootstrap_external>", line 940, in exec_module
  File "<frozen importlib._bootstrap>", line 241, in _call_with_frames_removed
  File "/Volumes/Personal Drive/GitHub/gdpr-ccpa-risk-pipeline/dags/gdpr_ccpa_risk_pipeline.py", line 42, in <module>
    with DAG(
         ^^^^
TypeError: DAG.__init__() got an unexpected keyword argument 'load_examples'
[2025-07-16T21:10:01.599-0700] {processor.py:841} WARNING - No viable dags retrieved from /Volumes/Personal Drive/GitHub/gdpr-ccpa-risk-pipeline/dags/gdpr_ccpa_risk_pipeline.py
[2025-07-16T21:10:02.182-0700] {processor.py:179} INFO - Processing /Volumes/Personal Drive/GitHub/gdpr-ccpa-risk-pipeline/dags/gdpr_ccpa_risk_pipeline.py took 3.665 seconds
[2025-07-16T21:10:41.314-0700] {processor.py:157} INFO - Started process (PID=12812) to work on /Volumes/Personal Drive/GitHub/gdpr-ccpa-risk-pipeline/dags/gdpr_ccpa_risk_pipeline.py
[2025-07-16T21:10:41.329-0700] {processor.py:829} INFO - Processing file /Volumes/Personal Drive/GitHub/gdpr-ccpa-risk-pipeline/dags/gdpr_ccpa_risk_pipeline.py for tasks to queue
[2025-07-16T21:10:41.332-0700] {logging_mixin.py:151} INFO - [2025-07-16T21:10:41.330-0700] {dagbag.py:539} INFO - Filling up the DagBag from /Volumes/Personal Drive/GitHub/gdpr-ccpa-risk-pipeline/dags/gdpr_ccpa_risk_pipeline.py
[2025-07-16T21:10:43.792-0700] {logging_mixin.py:151} INFO - [2025-07-16T21:10:43.775-0700] {dagbag.py:347} ERROR - Failed to import: /Volumes/Personal Drive/GitHub/gdpr-ccpa-risk-pipeline/dags/gdpr_ccpa_risk_pipeline.py
Traceback (most recent call last):
  File "/Volumes/Personal Drive/GitHub/gdpr-ccpa-risk-pipeline/venv/lib/python3.11/site-packages/airflow/models/dagbag.py", line 343, in parse
    loader.exec_module(new_module)
  File "<frozen importlib._bootstrap_external>", line 940, in exec_module
  File "<frozen importlib._bootstrap>", line 241, in _call_with_frames_removed
  File "/Volumes/Personal Drive/GitHub/gdpr-ccpa-risk-pipeline/dags/gdpr_ccpa_risk_pipeline.py", line 42, in <module>
    with DAG(
         ^^^^
TypeError: DAG.__init__() got an unexpected keyword argument 'load_examples'
[2025-07-16T21:10:43.795-0700] {processor.py:841} WARNING - No viable dags retrieved from /Volumes/Personal Drive/GitHub/gdpr-ccpa-risk-pipeline/dags/gdpr_ccpa_risk_pipeline.py
[2025-07-16T21:10:44.453-0700] {processor.py:179} INFO - Processing /Volumes/Personal Drive/GitHub/gdpr-ccpa-risk-pipeline/dags/gdpr_ccpa_risk_pipeline.py took 3.147 seconds
[2025-07-16T21:11:20.947-0700] {processor.py:157} INFO - Started process (PID=12835) to work on /Volumes/Personal Drive/GitHub/gdpr-ccpa-risk-pipeline/dags/gdpr_ccpa_risk_pipeline.py
[2025-07-16T21:11:20.954-0700] {processor.py:829} INFO - Processing file /Volumes/Personal Drive/GitHub/gdpr-ccpa-risk-pipeline/dags/gdpr_ccpa_risk_pipeline.py for tasks to queue
[2025-07-16T21:11:20.955-0700] {logging_mixin.py:151} INFO - [2025-07-16T21:11:20.955-0700] {dagbag.py:539} INFO - Filling up the DagBag from /Volumes/Personal Drive/GitHub/gdpr-ccpa-risk-pipeline/dags/gdpr_ccpa_risk_pipeline.py
[2025-07-16T21:11:24.484-0700] {logging_mixin.py:151} INFO - [2025-07-16T21:11:24.483-0700] {dagbag.py:347} ERROR - Failed to import: /Volumes/Personal Drive/GitHub/gdpr-ccpa-risk-pipeline/dags/gdpr_ccpa_risk_pipeline.py
Traceback (most recent call last):
  File "/Volumes/Personal Drive/GitHub/gdpr-ccpa-risk-pipeline/venv/lib/python3.11/site-packages/airflow/models/dagbag.py", line 343, in parse
    loader.exec_module(new_module)
  File "<frozen importlib._bootstrap_external>", line 940, in exec_module
  File "<frozen importlib._bootstrap>", line 241, in _call_with_frames_removed
  File "/Volumes/Personal Drive/GitHub/gdpr-ccpa-risk-pipeline/dags/gdpr_ccpa_risk_pipeline.py", line 42, in <module>
    with DAG(
         ^^^^
TypeError: DAG.__init__() got an unexpected keyword argument 'load_examples'
[2025-07-16T21:11:24.493-0700] {processor.py:841} WARNING - No viable dags retrieved from /Volumes/Personal Drive/GitHub/gdpr-ccpa-risk-pipeline/dags/gdpr_ccpa_risk_pipeline.py
[2025-07-16T21:11:25.956-0700] {processor.py:179} INFO - Processing /Volumes/Personal Drive/GitHub/gdpr-ccpa-risk-pipeline/dags/gdpr_ccpa_risk_pipeline.py took 5.011 seconds
[2025-07-16T21:33:36.588-0700] {processor.py:157} INFO - Started process (PID=13792) to work on /Volumes/Personal Drive/GitHub/gdpr-ccpa-risk-pipeline/dags/gdpr_ccpa_risk_pipeline.py
[2025-07-16T21:33:36.627-0700] {processor.py:829} INFO - Processing file /Volumes/Personal Drive/GitHub/gdpr-ccpa-risk-pipeline/dags/gdpr_ccpa_risk_pipeline.py for tasks to queue
[2025-07-16T21:33:36.628-0700] {logging_mixin.py:151} INFO - [2025-07-16T21:33:36.628-0700] {dagbag.py:539} INFO - Filling up the DagBag from /Volumes/Personal Drive/GitHub/gdpr-ccpa-risk-pipeline/dags/gdpr_ccpa_risk_pipeline.py
[2025-07-16T21:33:42.474-0700] {logging_mixin.py:151} INFO - [2025-07-16T21:33:42.463-0700] {dagbag.py:347} ERROR - Failed to import: /Volumes/Personal Drive/GitHub/gdpr-ccpa-risk-pipeline/dags/gdpr_ccpa_risk_pipeline.py
Traceback (most recent call last):
  File "/Volumes/Personal Drive/GitHub/gdpr-ccpa-risk-pipeline/venv/lib/python3.11/site-packages/airflow/models/dagbag.py", line 343, in parse
    loader.exec_module(new_module)
  File "<frozen importlib._bootstrap_external>", line 940, in exec_module
  File "<frozen importlib._bootstrap>", line 241, in _call_with_frames_removed
  File "/Volumes/Personal Drive/GitHub/gdpr-ccpa-risk-pipeline/dags/gdpr_ccpa_risk_pipeline.py", line 42, in <module>
    with DAG(
         ^^^^
TypeError: DAG.__init__() got an unexpected keyword argument 'load_examples'
[2025-07-16T21:33:42.478-0700] {processor.py:841} WARNING - No viable dags retrieved from /Volumes/Personal Drive/GitHub/gdpr-ccpa-risk-pipeline/dags/gdpr_ccpa_risk_pipeline.py
[2025-07-16T21:33:43.067-0700] {processor.py:179} INFO - Processing /Volumes/Personal Drive/GitHub/gdpr-ccpa-risk-pipeline/dags/gdpr_ccpa_risk_pipeline.py took 6.485 seconds
[2025-07-16T21:34:33.408-0700] {processor.py:157} INFO - Started process (PID=13818) to work on /Volumes/Personal Drive/GitHub/gdpr-ccpa-risk-pipeline/dags/gdpr_ccpa_risk_pipeline.py
[2025-07-16T21:34:33.417-0700] {processor.py:829} INFO - Processing file /Volumes/Personal Drive/GitHub/gdpr-ccpa-risk-pipeline/dags/gdpr_ccpa_risk_pipeline.py for tasks to queue
[2025-07-16T21:34:33.420-0700] {logging_mixin.py:151} INFO - [2025-07-16T21:34:33.420-0700] {dagbag.py:539} INFO - Filling up the DagBag from /Volumes/Personal Drive/GitHub/gdpr-ccpa-risk-pipeline/dags/gdpr_ccpa_risk_pipeline.py
[2025-07-16T21:34:39.647-0700] {logging_mixin.py:151} INFO - [2025-07-16T21:34:39.644-0700] {dagbag.py:347} ERROR - Failed to import: /Volumes/Personal Drive/GitHub/gdpr-ccpa-risk-pipeline/dags/gdpr_ccpa_risk_pipeline.py
Traceback (most recent call last):
  File "/Volumes/Personal Drive/GitHub/gdpr-ccpa-risk-pipeline/venv/lib/python3.11/site-packages/airflow/models/dagbag.py", line 343, in parse
    loader.exec_module(new_module)
  File "<frozen importlib._bootstrap_external>", line 940, in exec_module
  File "<frozen importlib._bootstrap>", line 241, in _call_with_frames_removed
  File "/Volumes/Personal Drive/GitHub/gdpr-ccpa-risk-pipeline/dags/gdpr_ccpa_risk_pipeline.py", line 42, in <module>
    with DAG(
         ^^^^
TypeError: DAG.__init__() got an unexpected keyword argument 'load_examples'
[2025-07-16T21:34:39.648-0700] {processor.py:841} WARNING - No viable dags retrieved from /Volumes/Personal Drive/GitHub/gdpr-ccpa-risk-pipeline/dags/gdpr_ccpa_risk_pipeline.py
[2025-07-16T21:34:40.416-0700] {processor.py:179} INFO - Processing /Volumes/Personal Drive/GitHub/gdpr-ccpa-risk-pipeline/dags/gdpr_ccpa_risk_pipeline.py took 7.015 seconds
[2025-07-16T21:35:20.490-0700] {processor.py:157} INFO - Started process (PID=13849) to work on /Volumes/Personal Drive/GitHub/gdpr-ccpa-risk-pipeline/dags/gdpr_ccpa_risk_pipeline.py
[2025-07-16T21:35:20.503-0700] {processor.py:829} INFO - Processing file /Volumes/Personal Drive/GitHub/gdpr-ccpa-risk-pipeline/dags/gdpr_ccpa_risk_pipeline.py for tasks to queue
[2025-07-16T21:35:20.508-0700] {logging_mixin.py:151} INFO - [2025-07-16T21:35:20.507-0700] {dagbag.py:539} INFO - Filling up the DagBag from /Volumes/Personal Drive/GitHub/gdpr-ccpa-risk-pipeline/dags/gdpr_ccpa_risk_pipeline.py
[2025-07-16T21:35:30.194-0700] {processor.py:839} INFO - DAG(s) dict_keys(['gdpr_ccpa_risk_pipeline']) retrieved from /Volumes/Personal Drive/GitHub/gdpr-ccpa-risk-pipeline/dags/gdpr_ccpa_risk_pipeline.py
[2025-07-16T21:35:37.257-0700] {logging_mixin.py:151} INFO - [2025-07-16T21:35:37.254-0700] {security.py:708} INFO - Not syncing DAG-level permissions for DAG 'DAG:gdpr_ccpa_risk_pipeline' as access control is unset.
[2025-07-16T21:35:37.260-0700] {logging_mixin.py:151} INFO - [2025-07-16T21:35:37.257-0700] {dag.py:2915} INFO - Sync 1 DAGs
[2025-07-16T21:35:37.410-0700] {logging_mixin.py:151} INFO - [2025-07-16T21:35:37.409-0700] {dag.py:3696} INFO - Setting next_dagrun for gdpr_ccpa_risk_pipeline to 2025-07-17T03:00:00+00:00, run_after=2025-07-17T04:00:00+00:00
[2025-07-16T21:35:37.534-0700] {processor.py:179} INFO - Processing /Volumes/Personal Drive/GitHub/gdpr-ccpa-risk-pipeline/dags/gdpr_ccpa_risk_pipeline.py took 17.054 seconds
[2025-07-16T21:40:27.081-0700] {processor.py:157} INFO - Started process (PID=14027) to work on /Volumes/Personal Drive/GitHub/gdpr-ccpa-risk-pipeline/dags/gdpr_ccpa_risk_pipeline.py
[2025-07-16T21:40:27.088-0700] {processor.py:829} INFO - Processing file /Volumes/Personal Drive/GitHub/gdpr-ccpa-risk-pipeline/dags/gdpr_ccpa_risk_pipeline.py for tasks to queue
[2025-07-16T21:40:27.090-0700] {logging_mixin.py:151} INFO - [2025-07-16T21:40:27.090-0700] {dagbag.py:539} INFO - Filling up the DagBag from /Volumes/Personal Drive/GitHub/gdpr-ccpa-risk-pipeline/dags/gdpr_ccpa_risk_pipeline.py
[2025-07-16T21:40:39.274-0700] {processor.py:839} INFO - DAG(s) dict_keys(['gdpr_ccpa_risk_pipeline']) retrieved from /Volumes/Personal Drive/GitHub/gdpr-ccpa-risk-pipeline/dags/gdpr_ccpa_risk_pipeline.py
[2025-07-16T21:40:41.696-0700] {logging_mixin.py:151} INFO - [2025-07-16T21:40:41.696-0700] {dag.py:2915} INFO - Sync 1 DAGs
[2025-07-16T21:40:42.053-0700] {logging_mixin.py:151} INFO - [2025-07-16T21:40:42.053-0700] {dag.py:3696} INFO - Setting next_dagrun for gdpr_ccpa_risk_pipeline to 2025-07-17T03:00:00+00:00, run_after=2025-07-17T04:00:00+00:00
[2025-07-16T21:40:42.823-0700] {processor.py:179} INFO - Processing /Volumes/Personal Drive/GitHub/gdpr-ccpa-risk-pipeline/dags/gdpr_ccpa_risk_pipeline.py took 15.739 seconds
[2025-07-16T22:28:59.079-0700] {processor.py:157} INFO - Started process (PID=16128) to work on /Volumes/Personal Drive/GitHub/gdpr-ccpa-risk-pipeline/dags/gdpr_ccpa_risk_pipeline.py
[2025-07-16T22:28:59.092-0700] {processor.py:829} INFO - Processing file /Volumes/Personal Drive/GitHub/gdpr-ccpa-risk-pipeline/dags/gdpr_ccpa_risk_pipeline.py for tasks to queue
[2025-07-16T22:28:59.099-0700] {logging_mixin.py:151} INFO - [2025-07-16T22:28:59.099-0700] {dagbag.py:539} INFO - Filling up the DagBag from /Volumes/Personal Drive/GitHub/gdpr-ccpa-risk-pipeline/dags/gdpr_ccpa_risk_pipeline.py
[2025-07-16T22:29:12.608-0700] {processor.py:839} INFO - DAG(s) dict_keys(['gdpr_ccpa_risk_pipeline']) retrieved from /Volumes/Personal Drive/GitHub/gdpr-ccpa-risk-pipeline/dags/gdpr_ccpa_risk_pipeline.py
[2025-07-16T22:29:20.267-0700] {logging_mixin.py:151} INFO - [2025-07-16T22:29:20.252-0700] {dag.py:2915} INFO - Sync 1 DAGs
[2025-07-16T22:29:21.365-0700] {logging_mixin.py:151} INFO - [2025-07-16T22:29:21.365-0700] {dag.py:3696} INFO - Setting next_dagrun for gdpr_ccpa_risk_pipeline to 2025-07-17T04:00:00+00:00, run_after=2025-07-17T05:00:00+00:00
[2025-07-16T22:29:22.212-0700] {processor.py:179} INFO - Processing /Volumes/Personal Drive/GitHub/gdpr-ccpa-risk-pipeline/dags/gdpr_ccpa_risk_pipeline.py took 23.148 seconds
[2025-07-16T23:21:46.959-0700] {processor.py:157} INFO - Started process (PID=18161) to work on /Volumes/Personal Drive/GitHub/gdpr-ccpa-risk-pipeline/dags/gdpr_ccpa_risk_pipeline.py
[2025-07-16T23:21:46.988-0700] {processor.py:829} INFO - Processing file /Volumes/Personal Drive/GitHub/gdpr-ccpa-risk-pipeline/dags/gdpr_ccpa_risk_pipeline.py for tasks to queue
[2025-07-16T23:21:46.988-0700] {logging_mixin.py:151} INFO - [2025-07-16T23:21:46.988-0700] {dagbag.py:539} INFO - Filling up the DagBag from /Volumes/Personal Drive/GitHub/gdpr-ccpa-risk-pipeline/dags/gdpr_ccpa_risk_pipeline.py
[2025-07-16T23:21:57.301-0700] {processor.py:839} INFO - DAG(s) dict_keys(['gdpr_ccpa_risk_pipeline']) retrieved from /Volumes/Personal Drive/GitHub/gdpr-ccpa-risk-pipeline/dags/gdpr_ccpa_risk_pipeline.py
[2025-07-16T23:21:59.372-0700] {logging_mixin.py:151} INFO - [2025-07-16T23:21:59.365-0700] {dag.py:2915} INFO - Sync 1 DAGs
[2025-07-16T23:21:59.573-0700] {logging_mixin.py:151} INFO - [2025-07-16T23:21:59.570-0700] {dag.py:3696} INFO - Setting next_dagrun for gdpr_ccpa_risk_pipeline to 2025-07-17T05:00:00+00:00, run_after=2025-07-17T06:00:00+00:00
[2025-07-16T23:21:59.758-0700] {processor.py:179} INFO - Processing /Volumes/Personal Drive/GitHub/gdpr-ccpa-risk-pipeline/dags/gdpr_ccpa_risk_pipeline.py took 12.811 seconds
[2025-07-16T23:55:32.755-0700] {processor.py:157} INFO - Started process (PID=19664) to work on /Volumes/Personal Drive/GitHub/gdpr-ccpa-risk-pipeline/dags/gdpr_ccpa_risk_pipeline.py
[2025-07-16T23:55:32.802-0700] {processor.py:829} INFO - Processing file /Volumes/Personal Drive/GitHub/gdpr-ccpa-risk-pipeline/dags/gdpr_ccpa_risk_pipeline.py for tasks to queue
[2025-07-16T23:55:32.804-0700] {logging_mixin.py:151} INFO - [2025-07-16T23:55:32.804-0700] {dagbag.py:539} INFO - Filling up the DagBag from /Volumes/Personal Drive/GitHub/gdpr-ccpa-risk-pipeline/dags/gdpr_ccpa_risk_pipeline.py
[2025-07-16T23:55:54.403-0700] {logging_mixin.py:151} INFO - [2025-07-16T23:55:54.403-0700] {plot.py:40} ERROR - Importing plotly failed. Interactive plots will not work.
[2025-07-16T23:55:54.640-0700] {processor.py:839} INFO - DAG(s) dict_keys(['gdpr_ccpa_risk_pipeline']) retrieved from /Volumes/Personal Drive/GitHub/gdpr-ccpa-risk-pipeline/dags/gdpr_ccpa_risk_pipeline.py
[2025-07-16T23:55:58.452-0700] {logging_mixin.py:151} INFO - [2025-07-16T23:55:58.430-0700] {dag.py:2915} INFO - Sync 1 DAGs
[2025-07-16T23:55:58.719-0700] {logging_mixin.py:151} INFO - [2025-07-16T23:55:58.719-0700] {dag.py:3696} INFO - Setting next_dagrun for gdpr_ccpa_risk_pipeline to 2025-07-17T06:00:00+00:00, run_after=2025-07-17T07:00:00+00:00
[2025-07-16T23:55:59.435-0700] {processor.py:179} INFO - Processing /Volumes/Personal Drive/GitHub/gdpr-ccpa-risk-pipeline/dags/gdpr_ccpa_risk_pipeline.py took 26.690 seconds
